<mujoco model="d1_550_description">
  <compiler angle="radian"/>

  <asset>
    <mesh name="base_link" content_type="model/stl" file="base_link.STL"/>
    <mesh name="Empty_Link1" content_type="model/stl" file="Empty_Link1.STL"/>
    <mesh name="Empty_Link2" content_type="model/stl" file="Empty_Link2.STL"/>
    <mesh name="Empty_Link3" content_type="model/stl" file="Empty_Link3.STL"/>
    <mesh name="Empty_Link4" content_type="model/stl" file="Empty_Link4.STL"/>
    <mesh name="Empty_Link5" content_type="model/stl" file="Empty_Link5.STL"/>
    <mesh name="Empty_Link6" content_type="model/stl" file="Empty_Link6.STL"/>
    <mesh name="Empty_Link_L" content_type="model/stl" file="Empty_Link_L.STL"/>
    <mesh name="Empty_Link_R" content_type="model/stl" file="Empty_Link_R.STL"/>
  </asset>

  <worldbody>
    <geom type="mesh" rgba="0.79216 0.81961 0.93333 1" mesh="base_link"/>
    <body name="Empty_Link1" pos="0 0 0.0738">
      <inertial pos="-0.0030892 6.1834e-05 0.031665" quat="0.70671 0.707502 0.000770411 -0.000758188" mass="0.14706" diaginertia="7.8054e-05 7.0773e-05 6.6897e-05"/>
      <joint name="Joint1" pos="0 0 0" axis="0 0 -1" range="-2.36 2.36" actuatorfrcrange="-3.33 3.33"/>
      <geom type="mesh" rgba="0.79216 0.81961 0.93333 1" mesh="Empty_Link1"/>
      <body name="Empty_Link2" pos="0 -0.0276 0.0578">
        <inertial pos="5.7801e-05 0.027243 0.19413" quat="1 -1.33226e-05 0.000385795 5.13981e-09" mass="0.20987" diaginertia="0.00025832 0.00023175 6.56789e-05"/>
        <joint name="Joint2" pos="0 0 0" axis="0 1 0" range="-1.57 1.57" actuatorfrcrange="-3.33 3.33"/>
        <geom type="mesh" rgba="0.79216 0.81961 0.93333 1" mesh="Empty_Link2"/>
        <body name="Empty_Link3" pos="0 -0.0004 0.27">
          <inertial pos="0.016105 0.0275 0.044231" quat="0.993422 -7.55011e-06 0.114514 -1.70588e-06" mass="0.064921" diaginertia="2.11366e-05 1.6024e-05 1.16974e-05"/>
          <joint name="Joint3" pos="0 0 0" axis="0 1 0" range="-1.57 1.57" actuatorfrcrange="-3.33 3.33"/>
          <geom type="mesh" rgba="0.79216 0.81961 0.93333 1" mesh="Empty_Link3"/>
          <body name="Empty_Link4" pos="0.05 0.0275 0.041325">
            <inertial pos="0.096072 3.157e-05 0.00025559" quat="-0.000571057 0.707854 0.000561397 0.706359" mass="0.081362" diaginertia="6.14152e-05 5.16631e-05 1.67237e-05"/>
            <joint name="Joint4" pos="0 0 0" axis="1 0 0" range="-2.36 2.36" actuatorfrcrange="-1.67 1.67"/>
            <geom type="mesh" rgba="0.79216 0.81961 0.93333 1" mesh="Empty_Link4"/>
            <body name="Empty_Link5" pos="0.15468 -0.0258 0.0001">
              <inertial pos="0.044211 0.025813 0.0054296" quat="0.998775 0.000335166 0.0494865 -0.000134048" mass="0.059846" diaginertia="1.47137e-05 1.2009e-05 9.92995e-06"/>
              <joint name="Joint5" pos="0 0 0" axis="0 1 0" range="-1.57 1.57" actuatorfrcrange="-1.67 1.67"/>
              <geom type="mesh" rgba="0.79216 0.81961 0.93333 1" mesh="Empty_Link5"/>
              <body name="Empty_Link6" pos="0.0777 0.025822 -0.0010718">
                <inertial pos="0.03844 -0.00044094 0.0060952" quat="0.706494 0.706473 -0.0300475 0.0293186" mass="0.12117" diaginertia="0.000119981 0.0001057 3.24659e-05"/>
                <joint name="Joint6" pos="0 0 0" axis="1 0 0" range="-2.36 2.36" actuatorfrcrange="-1.67 1.67"/>
                <geom type="mesh" rgba="0.79216 0.81961 0.93333 1" mesh="Empty_Link6"/>
                <body name="Empty_Link_L" pos="0.0718 -0.033778 0.0031">
                  <inertial pos="0.018562 -0.0073492 -0.0034988" quat="0.472049 0.472056 0.526471 0.526461" mass="0.01333" diaginertia="2.3953e-06 1.8134e-06 1.0065e-06"/>
                  <joint name="Joint_L" pos="0 0 0" axis="0 1 0" type="slide" range="0 0.033" actuatorfrcrange="-15 15"/>
                  <geom type="mesh" rgba="0.79216 0.81961 0.93333 1" mesh="Empty_Link_L"/>
                </body>
                <body name="Empty_Link_R" pos="0.0718 0.033022 0.0031">
                  <inertial pos="0.018562 0.0073492 -0.0035012" quat="0.526471 0.526461 0.472049 0.472056" mass="0.01333" diaginertia="2.3953e-06 1.8134e-06 1.0065e-06"/>
                  <joint name="Joint_R" pos="0 0 0" axis="0 -1 0" type="slide" range="0 0.033" actuatorfrcrange="-15 15"/>
                  <geom type="mesh" rgba="0.79216 0.81961 0.93333 1" mesh="Empty_Link_R"/>
                </body>
              </body>
            </body>
          </body>
        </body>
      </body>
    </body>
  </worldbody>
</mujoco>
