<mujoco model="go2">
  <compiler angle="radian" meshdir="assets" autolimits="true"/>

  <option iterations="1" ls_iterations="5" timestep="0.004" integrator="Euler">
    <flag eulerdamp="disable"/>
  </option>

  <custom>
    <numeric data="30" name="max_contact_points"/>
    <numeric data="12" name="max_geom_pairs"/>
  </custom>

  <default>
    <default class="go2">
      <geom condim="1"/>
      <joint axis="0 1 0" damping="2" armature="0.01"/>
      <general forcerange="-24 24" biastype="affine" gainprm="50 0 0" biasprm="0 -50 -0.5"/>

      <default class="abduction">
        <joint axis="1 0 0" range="-1.0472 1.0472"/>
        <general ctrlrange="-0.9472 0.9472"/>
      </default>
      <default class="hip">
        <joint range="-1.5708 3.4907"/>
        <general ctrlrange="-1.4 2.5"/>
      </default>
      <default class="knee">
        <joint range="-2.7227 -0.83776"/>
        <general ctrlrange="-2.6227 -0.84776"/>
      </default>
      <default class="visual">
        <geom type="mesh" contype="0" conaffinity="0" group="2"/>
      </default>
      <default class="go2foot">
        <site pos="0 0 -0.213" type="sphere" size="0.023" group="5"/>
        <geom rgba="0.231373 0.380392 0.705882 1"/>
      </default>
      <default class="collision">
        <geom group="3"/>
        <default class="foot">
          <geom type="sphere" size="0.0175" pos="-0.002 0 -0.213" solimp="0.9 .95 0.023" condim="3"/>
        </default>
      </default>
    </default>
  </default>

  <asset>
    <material name="metal" rgba=".9 .95 .95 1"/>
    <material name="black" rgba="0 0 0 1"/>
    <material name="white" rgba="1 1 1 1"/>
    <material name="gray" rgba="0.671705 0.692426 0.774270 1"/>

    <mesh file="base_0.obj"/>
    <mesh file="base_1.obj"/>
    <mesh file="base_2.obj"/>
    <mesh file="base_3.obj"/>
    <mesh file="base_4.obj"/>
    <mesh file="hip_0.obj"/>
    <mesh file="hip_1.obj"/>
    <mesh file="thigh_0.obj"/>
    <mesh file="thigh_1.obj"/>
    <mesh file="thigh_mirror_0.obj"/>
    <mesh file="thigh_mirror_1.obj"/>
    <mesh file="calf_0.obj"/>
    <mesh file="calf_1.obj"/>
    <mesh file="calf_mirror_0.obj"/>
    <mesh file="calf_mirror_1.obj"/>
    <mesh file="foot.obj"/>
    <mesh name="base_link" content_type="model/stl" file="base_link.STL"/>
    <mesh name="Empty_Link1" content_type="model/stl" file="Empty_Link1.STL"/>
    <mesh name="Empty_Link2" content_type="model/stl" file="Empty_Link2.STL"/>
    <mesh name="Empty_Link3" content_type="model/stl" file="Empty_Link3.STL"/>
    <mesh name="Empty_Link4" content_type="model/stl" file="Empty_Link4.STL"/>
    <mesh name="Empty_Link5" content_type="model/stl" file="Empty_Link5.STL"/>
    <mesh name="Empty_Link6" content_type="model/stl" file="Empty_Link6.STL"/>
    <mesh name="Empty_Link_L" content_type="model/stl" file="Empty_Link_L.STL"/>
    <mesh name="Empty_Link_R" content_type="model/stl" file="Empty_Link_R.STL"/>
  </asset>

  <worldbody>
    <body name="base" pos="0 0 0.445" childclass="go2">
      <camera name="track" pos="0.846 -1.465 0.916" xyaxes="0.866 0.500 0.000 -0.171 0.296 0.940" mode="trackcom"/>
      <inertial pos="0.021112 0 -0.005366" quat="-0.000543471 0.713435 -0.00173769 0.700719" mass="6.921"
        diaginertia="0.107027 0.0980771 0.0244531"/>
      <freejoint/>
      <geom mesh="base_0" material="black" class="visual"/>
      <geom mesh="base_1" material="black" class="visual"/>
      <geom mesh="base_2" material="black" class="visual"/>
      <geom mesh="base_3" material="white" class="visual"/>
      <geom mesh="base_4" material="gray" class="visual"/>
      <geom name="test_0" size="0.057 0.04675 0.057" class="collision"/>
      <geom name="test_1" size="0.05 0.045" pos="0.285 0 0.01" class="collision"/>
      <geom name="test_2" size="0.047" pos="0.293 0 -0.06" class="collision"/>
      <site name="imu" pos="-0.02557 0 0.04232"/>
      <geom type="mesh" rgba="0.79216 0.81961 0.93333 1" pos="-0.03 0 0.06" mesh="base_link"/>
      <body name="Empty_Link1" pos="-0.03 0 0.1338">
        <inertial pos="-0.0030892 6.1834e-05 0.031665" quat="0.70671 0.707502 0.000770411 -0.000758188" mass="0.14706" diaginertia="7.8054e-05 7.0773e-05 6.6897e-05"/>
        <joint name="Joint1" pos="0 0 0" axis="0 0 -1" range="-2.36 2.36" actuatorfrcrange="-3.33 3.33"/>
        <geom type="mesh" rgba="0.79216 0.81961 0.93333 1" mesh="Empty_Link1"/>
        <body name="Empty_Link2" pos="0 -0.0276 0.0578">
          <inertial pos="5.7801e-05 0.027243 0.19413" quat="1 -1.33226e-05 0.000385795 5.13981e-09" mass="0.20987" diaginertia="0.00025832 0.00023175 6.56789e-05"/>
          <joint name="Joint2" pos="0 0 0" axis="0 1 0" range="-1.57 1.57" actuatorfrcrange="-3.33 3.33"/>
          <geom type="mesh" rgba="0.79216 0.81961 0.93333 1" mesh="Empty_Link2"/>
          <body name="Empty_Link3" pos="0 -0.0004 0.27">
            <inertial pos="0.016105 0.0275 0.044231" quat="0.993422 -7.55011e-06 0.114514 -1.70588e-06" mass="0.064921" diaginertia="2.11366e-05 1.6024e-05 1.16974e-05"/>
            <joint name="Joint3" pos="0 0 0" axis="0 1 0" range="-1.57 1.57" actuatorfrcrange="-3.33 3.33"/>
            <geom type="mesh" rgba="0.79216 0.81961 0.93333 1" mesh="Empty_Link3"/>
            <body name="Empty_Link4" pos="0.05 0.0275 0.041325">
              <inertial pos="0.096072 3.157e-05 0.00025559" quat="-0.000571057 0.707854 0.000561397 0.706359" mass="0.081362" diaginertia="6.14152e-05 5.16631e-05 1.67237e-05"/>
              <joint name="Joint4" pos="0 0 0" axis="1 0 0" range="-2.36 2.36" actuatorfrcrange="-1.67 1.67"/>
              <geom type="mesh" rgba="0.79216 0.81961 0.93333 1" mesh="Empty_Link4"/>
              <body name="Empty_Link5" pos="0.15468 -0.0258 0.0001">
                <inertial pos="0.044211 0.025813 0.0054296" quat="0.998775 0.000335166 0.0494865 -0.000134048" mass="0.059846" diaginertia="1.47137e-05 1.2009e-05 9.92995e-06"/>
                <joint name="Joint5" pos="0 0 0" axis="0 1 0" range="-1.57 1.57" actuatorfrcrange="-1.67 1.67"/>
                <geom type="mesh" rgba="0.79216 0.81961 0.93333 1" mesh="Empty_Link5"/>
                <body name="Empty_Link6" pos="0.0777 0.025822 -0.0010718">
                  <inertial pos="0.03844 -0.00044094 0.0060952" quat="0.706494 0.706473 -0.0300475 0.0293186" mass="0.12117" diaginertia="0.000119981 0.0001057 3.24659e-05"/>
                  <joint name="Joint6" pos="0 0 0" axis="1 0 0" range="-2.36 2.36" actuatorfrcrange="-1.67 1.67"/>
                  <geom type="mesh" rgba="0.79216 0.81961 0.93333 1" mesh="Empty_Link6"/>
                  <body name="Empty_Link_L" pos="0.0718 -0.033778 0.0031">
                    <inertial pos="0.018562 -0.0073492 -0.0034988" quat="0.472049 0.472056 0.526471 0.526461" mass="0.01333" diaginertia="2.3953e-06 1.8134e-06 1.0065e-06"/>
                    <joint name="Joint_L" pos="0 0 0" axis="0 1 0" type="slide" range="0 0.033" actuatorfrcrange="-15 15"/>
                    <geom type="mesh" rgba="0.79216 0.81961 0.93333 1" mesh="Empty_Link_L"/>
                  </body>
                  <body name="Empty_Link_R" pos="0.0718 0.033022 0.0031">
                    <inertial pos="0.018562 0.0073492 -0.0035012" quat="0.526471 0.526461 0.472049 0.472056" mass="0.01333" diaginertia="2.3953e-06 1.8134e-06 1.0065e-06"/>
                    <joint name="Joint_R" pos="0 0 0" axis="0 -1 0" type="slide" range="0 0.033" actuatorfrcrange="-15 15"/>
                    <geom type="mesh" rgba="0.79216 0.81961 0.93333 1" mesh="Empty_Link_R"/>
                  </body>
                </body>
              </body>
            </body>
          </body>
        </body>
      </body>
      <body name="FL_hip" pos="0.1934 0.0465 0">
        <inertial pos="-0.0054 0.00194 -0.000105" quat="0.497014 0.499245 0.505462 0.498237" mass="0.678"
          diaginertia="0.00088403 0.000596003 0.000479967"/>
        <joint name="FL_hip_joint" class="abduction"/>
        <geom mesh="hip_0" material="metal" class="visual"/>
        <geom mesh="hip_1" material="gray" class="visual"/>
        <geom name="fl_hip_0" size="0.046 0.02" pos="0 0.08 0" quat="1 1 0 0" class="collision"/>
        <body name="FL_thigh" pos="0 0.0955 0">
          <inertial pos="-0.00374 -0.0223 -0.0327" quat="0.829533 0.0847635 -0.0200632 0.551623" mass="1.152"
            diaginertia="0.00594973 0.00584149 0.000878787"/>
          <joint name="FL_thigh_joint" class="hip"/>
          <geom mesh="thigh_0" material="metal" class="visual"/>
          <geom mesh="thigh_1" material="gray" class="visual"/>
          <geom name="fl_thigh_0" size="0.017 0.01225 0.017" pos="-0.015 0 -0.1955" quat="0.707107 0 0.707107 0" class="collision"/>
          <body name="FL_calf" pos="0 0 -0.213">
            <inertial pos="0.00629595 -0.000622121 -0.141417" quat="0.710672 0.00154099 -0.00450087 0.703508"
              mass="0.241352" diaginertia="0.0014901 0.00146356 5.31397e-05"/>
            <joint name="FL_calf_joint" class="knee"/>
            <geom mesh="calf_0" material="gray" class="visual"/>
            <geom mesh="calf_1" material="black" class="visual"/>
            <geom name="fl_calf_0" size="0.012 0.06" pos="0.008 0 -0.06" quat="0.994493 0 -0.104807 0" class="collision"/>
            <geom name="fl_calf_1" size="0.011 0.0325" pos="0.02 0 -0.148" quat="0.999688 0 0.0249974 0" class="collision"/>
            <geom pos="0 0 -0.213" mesh="foot" class="visual" material="black"/>
            <geom name="FL" class="foot"/>
            <site name="FL" class="go2foot"/>
          </body>
        </body>
      </body>
      <body name="FR_hip" pos="0.1934 -0.0465 0">
        <inertial pos="-0.0054 -0.00194 -0.000105" quat="0.498237 0.505462 0.499245 0.497014" mass="0.678"
          diaginertia="0.00088403 0.000596003 0.000479967"/>
        <joint name="FR_hip_joint" class="abduction"/>
        <geom mesh="hip_0" material="metal" class="visual" quat="4.63268e-05 1 0 0"/>
        <geom mesh="hip_1" material="gray" class="visual" quat="4.63268e-05 1 0 0"/>
        <geom name="fr_hip_0" size="0.046 0.02" pos="0 -0.08 0" quat="0.707107 0.707107 0 0" class="collision"/>
        <body name="FR_thigh" pos="0 -0.0955 0">
          <inertial pos="-0.00374 0.0223 -0.0327" quat="0.551623 -0.0200632 0.0847635 0.829533" mass="1.152"
            diaginertia="0.00594973 0.00584149 0.000878787"/>
          <joint name="FR_thigh_joint" class="hip"/>
          <geom mesh="thigh_mirror_0" material="metal" class="visual"/>
          <geom mesh="thigh_mirror_1" material="gray" class="visual"/>
          <geom name="fr_thigh_0" size="0.017 0.01225 0.017" pos="-0.015 0 -0.1955" quat="0.707107 0 0.707107 0" class="collision"/>
          <body name="FR_calf" pos="0 0 -0.213">
            <inertial pos="0.00629595 0.000622121 -0.141417" quat="0.703508 -0.00450087 0.00154099 0.710672"
              mass="0.241352" diaginertia="0.0014901 0.00146356 5.31397e-05"/>
            <joint name="FR_calf_joint" class="knee"/>
            <geom mesh="calf_mirror_0" material="gray" class="visual"/>
            <geom mesh="calf_mirror_1" material="black" class="visual"/>
            <geom name="fr_calf_0" size="0.013 0.06" pos="0.01 0 -0.06" quat="0.995004 0 -0.0998334 0" class="collision"/>
            <geom name="fr_calf_1" size="0.011 0.0325" pos="0.02 0 -0.148" quat="0.999688 0 0.0249974 0" class="collision"/>
            <geom pos="0 0 -0.213" mesh="foot" class="visual" material="black"/>
            <geom name="FR" class="foot"/>
            <site name="FR" class="go2foot"/>
          </body>
        </body>
      </body>
      <body name="RL_hip" pos="-0.1934 0.0465 0">
        <inertial pos="0.0054 0.00194 -0.000105" quat="0.505462 0.498237 0.497014 0.499245" mass="0.678"
          diaginertia="0.00088403 0.000596003 0.000479967"/>
        <joint name="RL_hip_joint" class="abduction"/>
        <geom mesh="hip_0" material="metal" class="visual" quat="4.63268e-05 0 1 0"/>
        <geom mesh="hip_1" material="gray" class="visual" quat="4.63268e-05 0 1 0"/>
        <geom name="rl_hip_0" size="0.046 0.02" pos="0 0.08 0" quat="0.707107 0.707107 0 0" class="collision"/>
        <body name="RL_thigh" pos="0 0.0955 0">
          <inertial pos="-0.00374 -0.0223 -0.0327" quat="0.829533 0.0847635 -0.0200632 0.551623" mass="1.152"
            diaginertia="0.00594973 0.00584149 0.000878787"/>
          <joint name="RL_thigh_joint" class="hip"/>
          <geom mesh="thigh_0" material="metal" class="visual"/>
          <geom mesh="thigh_1" material="gray" class="visual"/>
          <geom name="rl_thigh_0" size="0.017 0.01225 0.017" pos="-0.015 0 -0.1955" quat="0.707107 0 0.707107 0" class="collision"/>
          <body name="RL_calf" pos="0 0 -0.213">
            <inertial pos="0.00629595 -0.000622121 -0.141417" quat="0.710672 0.00154099 -0.00450087 0.703508"
              mass="0.241352" diaginertia="0.0014901 0.00146356 5.31397e-05"/>
            <joint name="RL_calf_joint" class="knee"/>
            <geom mesh="calf_0" material="gray" class="visual"/>
            <geom mesh="calf_1" material="black" class="visual"/>
            <geom name="rl_calf_0" size="0.013 0.06" pos="0.01 0 -0.06" quat="0.995004 0 -0.0998334 0" class="collision"/>
            <geom name="rl_calf_1" size="0.011 0.0325" pos="0.02 0 -0.148" quat="0.999688 0 0.0249974 0" class="collision"/>
            <geom pos="0 0 -0.213" mesh="foot" class="visual" material="black"/>
            <geom name="RL" class="foot"/>
            <site name="RL" class="go2foot"/>
          </body>
        </body>
      </body>
      <body name="RR_hip" pos="-0.1934 -0.0465 0">
        <inertial pos="0.0054 -0.00194 -0.000105" quat="0.499245 0.497014 0.498237 0.505462" mass="0.678"
          diaginertia="0.00088403 0.000596003 0.000479967"/>
        <joint name="RR_hip_joint" class="abduction"/>
        <geom mesh="hip_0" material="metal" class="visual" quat="2.14617e-09 4.63268e-05 4.63268e-05 -1"/>
        <geom mesh="hip_1" material="gray" class="visual" quat="2.14617e-09 4.63268e-05 4.63268e-05 -1"/>
        <geom name="rr_hip_0" size="0.046 0.02" pos="0 -0.08 0" quat="0.707107 0.707107 0 0" class="collision"/>
        <body name="RR_thigh" pos="0 -0.0955 0">
          <inertial pos="-0.00374 0.0223 -0.0327" quat="0.551623 -0.0200632 0.0847635 0.829533" mass="1.152"
            diaginertia="0.00594973 0.00584149 0.000878787"/>
          <joint name="RR_thigh_joint" class="hip"/>
          <geom mesh="thigh_mirror_0" material="metal" class="visual"/>
          <geom mesh="thigh_mirror_1" material="gray" class="visual"/>
          <geom name="rr_thigh_0" size="0.017 0.01225 0.017" pos="-0.015 0 -0.1955" quat="0.707107 0 0.707107 0" class="collision"/>
          <body name="RR_calf" pos="0 0 -0.213">
            <inertial pos="0.00629595 0.000622121 -0.141417" quat="0.703508 -0.00450087 0.00154099 0.710672"
              mass="0.241352" diaginertia="0.0014901 0.00146356 5.31397e-05"/>
            <joint name="RR_calf_joint" class="knee"/>
            <geom mesh="calf_mirror_0" material="gray" class="visual"/>
            <geom mesh="calf_mirror_1" material="black" class="visual"/>
            <geom name="rr_calf_0" size="0.013 0.06" pos="0.01 0 -0.06" quat="0.995004 0 -0.0998334 0" class="collision"/>
            <geom name="rr_calf_1" size="0.011 0.0325" pos="0.02 0 -0.148" quat="0.999688 0 0.0249974 0" class="collision"/>
            <geom pos="0 0 -0.213" mesh="foot" class="visual" material="black"/>
            <geom name="RR" class="foot"/>
            <site name="RR" class="go2foot"/>
          </body>
        </body>
      </body>
    </body>
  </worldbody>

  <actuator>
    <general class="abduction" name="FR_hip" joint="FR_hip_joint"/>
    <general class="hip" name="FR_thigh" joint="FR_thigh_joint"/>
    <general class="knee" name="FR_calf" joint="FR_calf_joint"/>
    <general class="abduction" name="FL_hip" joint="FL_hip_joint"/>
    <general class="hip" name="FL_thigh" joint="FL_thigh_joint"/>
    <general class="knee" name="FL_calf" joint="FL_calf_joint"/>
    <general class="abduction" name="RR_hip" joint="RR_hip_joint"/>
    <general class="hip" name="RR_thigh" joint="RR_thigh_joint"/>
    <general class="knee" name="RR_calf" joint="RR_calf_joint"/>
    <general class="abduction" name="RL_hip" joint="RL_hip_joint"/>
    <general class="hip" name="RL_thigh" joint="RL_thigh_joint"/>
    <general class="knee" name="RL_calf" joint="RL_calf_joint"/>
    <general name="Empty_Link1" joint="Joint1"/>
    <general name="Empty_Link2" joint="Joint2"/>
    <general name="Empty_Link3" joint="Joint3"/>
    <general name="Empty_Link4" joint="Joint4"/>
    <general name="Empty_Link5" joint="Joint5"/>
    <general name="Empty_Link6" joint="Joint6"/>
    <general name="Empty_Link_L" joint="Joint_L"/>
    <general name="Empty_Link_R" joint="Joint_R"/>
  </actuator>

  <sensor>
    <jointpos joint="FL_hip_joint" name="abduction_front_left_pos"/>
    <jointpos joint="FL_thigh_joint" name="hip_front_left_pos"/>
    <jointpos joint="FL_calf_joint" name="knee_front_left_pos"/>
    <jointpos joint="RL_hip_joint" name="abduction_hind_left_pos"/>
    <jointpos joint="RL_thigh_joint" name="hip_hind_left_pos"/>
    <jointpos joint="RL_calf_joint" name="knee_hind_left_pos"/>
    <jointpos joint="FR_hip_joint" name="abduction_front_right_pos"/>
    <jointpos joint="FR_thigh_joint" name="hip_front_right_pos"/>
    <jointpos joint="FR_calf_joint" name="knee_front_right_pos"/>
    <jointpos joint="RR_hip_joint" name="abduction_hind_right_pos"/>
    <jointpos joint="RR_thigh_joint" name="hip_hind_right_pos"/>
    <jointpos joint="RR_calf_joint" name="knee_hind_right_pos"/>
    <jointvel joint="FL_hip_joint" name="abduction_front_left_vel"/>
    <jointvel joint="FL_thigh_joint" name="hip_front_left_vel"/>
    <jointvel joint="FL_calf_joint" name="knee_front_left_vel"/>
    <jointvel joint="RL_hip_joint" name="abduction_hind_left_vel"/>
    <jointvel joint="RL_thigh_joint" name="hip_hind_left_vel"/>
    <jointvel joint="RL_calf_joint" name="knee_hind_left_vel"/>
    <jointvel joint="FR_hip_joint" name="abduction_front_right_vel"/>
    <jointvel joint="FR_thigh_joint" name="hip_front_right_vel"/>
    <jointvel joint="FR_calf_joint" name="knee_front_right_vel"/>
    <jointvel joint="RR_hip_joint" name="abduction_hind_right_vel"/>
    <jointvel joint="RR_thigh_joint" name="hip_hind_right_vel"/>
    <jointvel joint="RR_calf_joint" name="knee_hind_right_vel"/>

    <gyro site="imu" name="gyro"/>
    <accelerometer site="imu" name="accelerometer"/>
    <velocimeter site="imu" name="local_linvel"/>
    <framezaxis objtype="site" objname="imu" name="upvector"/>
    <framequat objtype="site" objname="imu" name="orientation"/>
    <framepos objtype="site" objname="imu" name="global_position"/>
    <framelinvel objtype="site" objname="imu" name="global_linvel"/>
    <frameangvel objtype="site" objname="imu" name="global_angvel"/>

    <framelinvel objtype="site" objname="FR" name="FR_global_linvel"/>
    <framelinvel objtype="site" objname="FL" name="FL_global_linvel"/>
    <framelinvel objtype="site" objname="RR" name="RR_global_linvel"/>
    <framelinvel objtype="site" objname="RL" name="RL_global_linvel"/>

    <framepos objtype="site" objname="FR" name="FR_pos" reftype="site" refname="imu"/>
    <framepos objtype="site" objname="FL" name="FL_pos" reftype="site" refname="imu"/>
    <framepos objtype="site" objname="RR" name="RR_pos" reftype="site" refname="imu"/>
    <framepos objtype="site" objname="RL" name="RL_pos" reftype="site" refname="imu"/>
  </sensor>
</mujoco>

